Workbook

Sheet Índice
B2: Índice de Requerimientos — IncluTec
B3: Plataforma web y móvil de vinculación laboral para personas con discapacidad · Estadía ISC · UPQ · Entrega: 28 de octubre de 2026
B5: Interfaces: Requerimientos Funcionales y No Funcionales por hoja
B6: # | C6: Hoja | D6: Interfaz | E6: Módulo / Rol | F6: # RF | G6: # RNF | H6: Avance RF | I6: Ir
B7: 1 | C7: MOV-00 Splash | D7: MOV-00 — Splash | E7: Móvil / Compartida | F7: =COUNTA('MOV-00 Splash'!B6:B7) -> 2 | G7: =COUNTA('MOV-00 Splash'!B13:B26) -> 14 | H7: =AVERAGE('MOV-00 Splash'!F6:F7) -> 0 | I7: Abrir →
B8: 2 | C8: MOV-01 Login móvil | D8: MOV-01 — Inicio de sesión (móvil) | E8: Móvil / Compartida | F8: =COUNTA('MOV-01 Login móvil'!B6:B10) -> 5 | G8: =COUNTA('MOV-01 Login móvil'!B16:B34) -> 19 | H8: =AVERAGE('MOV-01 Login móvil'!F6:F10) -> 0 | I8: Abrir →
B9: 3 | C9: MOV-02 Registro | D9: MOV-02 — Registro de cuenta | E9: Móvil / Compartida | F9: =COUNTA('MOV-02 Registro'!B6:B12) -> 7 | G9: =COUNTA('MOV-02 Registro'!B18:B41) -> 24 | H9: =AVERAGE('MOV-02 Registro'!F6:F12) -> 0 | I9: Abrir →
B10: 4 | C10: MOV-03 Recuperar contraseña | D10: MOV-03 — Recuperar contraseña | E10: Móvil / Compartida | F10: =COUNTA('MOV-03 Recuperar contraseña'!B6:B9) -> 4 | G10: =COUNTA('MOV-03 Recuperar contraseña'!B15:B33) -> 19 | H10: =AVERAGE('MOV-03 Recuperar contraseña'!F6:F9) -> 0 | I10: Abrir →
B11: 5 | C11: MOV-04 Notificaciones | D11: MOV-04 — Notificaciones | E11: Móvil / Compartida | F11: =COUNTA('MOV-04 Notificaciones'!B6:B11) -> 6 | G11: =COUNTA('MOV-04 Notificaciones'!B17:B34) -> 18 | H11: =AVERAGE('MOV-04 Notificaciones'!F6:F11) -> 0 | I11: Abrir →
B12: 6 | C12: CAN-01 Vacantes | D12: CAN-01 — Vacantes (inicio del candidato) | E12: Móvil / Candidato | F12: =COUNTA('CAN-01 Vacantes'!B6:B11) -> 6 | G12: =COUNTA('CAN-01 Vacantes'!B17:B30) -> 14 | H12: =AVERAGE('CAN-01 Vacantes'!F6:F11) -> 0 | I12: Abrir →
B13: 7 | C13: CAN-02 Detalle vacante | D13: CAN-02 — Detalle de vacante | E13: Móvil / Candidato | F13: =COUNTA('CAN-02 Detalle vacante'!B6:B14) -> 9 | G13: =COUNTA('CAN-02 Detalle vacante'!B20:B38) -> 19 | H13: =AVERAGE('CAN-02 Detalle vacante'!F6:F14) -> 0 | I13: Abrir →
B14: 8 | C14: CAN-03 Mi perfil | D14: CAN-03 — Mi perfil | E14: Móvil / Candidato | F14: =COUNTA('CAN-03 Mi perfil'!B6:B12) -> 7 | G14: =COUNTA('CAN-03 Mi perfil'!B18:B36) -> 19 | H14: =AVERAGE('CAN-03 Mi perfil'!F6:F12) -> 0 | I14: Abrir →
B15: 9 | C15: CAN-04 Mi CV | D15: CAN-04 — Mi CV | E15: Móvil / Candidato | F15: =COUNTA('CAN-04 Mi CV'!B6:B11) -> 6 | G15: =COUNTA('CAN-04 Mi CV'!B17:B35) -> 19 | H15: =AVERAGE('CAN-04 Mi CV'!F6:F11) -> 0 | I15: Abrir →
B16: 10 | C16: CAN-05 Postulaciones | D16: CAN-05 — Mis postulaciones | E16: Móvil / Candidato | F16: =COUNTA('CAN-05 Postulaciones'!B6:B10) -> 5 | G16: =COUNTA('CAN-05 Postulaciones'!B16:B29) -> 14 | H16: =AVERAGE('CAN-05 Postulaciones'!F6:F10) -> 0 | I16: Abrir →
B17: 11 | C17: CAN-06 Detalle postulación | D17: CAN-06 — Detalle de postulación y entrevista | E17: Móvil / Candidato | F17: =COUNTA('CAN-06 Detalle postulación'!B6:B11) -> 6 | G17: =COUNTA('CAN-06 Detalle postulación'!B17:B34) -> 18 | H17: =AVERAGE('CAN-06 Detalle postulación'!F6:F11) -> 0 | I17: Abrir →
B18: 12 | C18: CAN-07 Empresas | D18: CAN-07 — Empresas | E18: Móvil / Candidato | F18: =COUNTA('CAN-07 Empresas'!B6:B9) -> 4 | G18: =COUNTA('CAN-07 Empresas'!B15:B28) -> 14 | H18: =AVERAGE('CAN-07 Empresas'!F6:F9) -> 0 | I18: Abrir →
B19: 13 | C19: REC-01 Organización | D19: REC-01 — Perfil de la organización | E19: Móvil / Reclutador | F19: =COUNTA('REC-01 Organización'!B6:B10) -> 5 | G19: =COUNTA('REC-01 Organización'!B16:B29) -> 14 | H19: =AVERAGE('REC-01 Organización'!F6:F10) -> 0 | I19: Abrir →
B20: 14 | C20: REC-02 Mis vacantes | D20: REC-02 — Mis vacantes | E20: Móvil / Reclutador | F20: =COUNTA('REC-02 Mis vacantes'!B6:B11) -> 6 | G20: =COUNTA('REC-02 Mis vacantes'!B17:B30) -> 14 | H20: =AVERAGE('REC-02 Mis vacantes'!F6:F11) -> 0 | I20: Abrir →
B21: 15 | C21: REC-03 Crear vacante | D21: REC-03 — Crear / editar vacante | E21: Móvil / Reclutador | F21: =COUNTA('REC-03 Crear vacante'!B6:B11) -> 6 | G21: =COUNTA('REC-03 Crear vacante'!B17:B30) -> 14 | H21: =AVERAGE('REC-03 Crear vacante'!F6:F11) -> 0 | I21: Abrir →
B22: 16 | C22: REC-04 Postulados | D22: REC-04 — Candidatos postulados | E22: Móvil / Reclutador | F22: =COUNTA('REC-04 Postulados'!B6:B10) -> 5 | G22: =COUNTA('REC-04 Postulados'!B16:B29) -> 14 | H22: =AVERAGE('REC-04 Postulados'!F6:F10) -> 0 | I22: Abrir →
B23: 17 | C23: REC-05 Detalle postulado | D23: REC-05 — Detalle del postulado | E23: Móvil / Reclutador | F23: =COUNTA('REC-05 Detalle postulado'!B6:B12) -> 7 | G23: =COUNTA('REC-05 Detalle postulado'!B18:B40) -> 23 | H23: =AVERAGE('REC-05 Detalle postulado'!F6:F12) -> 0 | I23: Abrir →
B24: 18 | C24: REC-06 Agenda | D24: REC-06 — Agenda de entrevistas | E24: Móvil / Reclutador | F24: =COUNTA('REC-06 Agenda'!B6:B10) -> 5 | G24: =COUNTA('REC-06 Agenda'!B16:B33) -> 18 | H24: =AVERAGE('REC-06 Agenda'!F6:F10) -> 0 | I24: Abrir →
B25: 19 | C25: WEB-01 Login web | D25: WEB-01 — Inicio de sesión (web) | E25: Web / Administrador | F25: =COUNTA('WEB-01 Login web'!B6:B10) -> 5 | G25: =COUNTA('WEB-01 Login web'!B16:B29) -> 14 | H25: =AVERAGE('WEB-01 Login web'!F6:F10) -> 0 | I25: Abrir →
B26: 20 | C26: WEB-02 Dashboard | D26: WEB-02 — Dashboard y estadísticas | E26: Web / Administrador | F26: =COUNTA('WEB-02 Dashboard'!B6:B12) -> 7 | G26: =COUNTA('WEB-02 Dashboard'!B18:B30) -> 13 | H26: =AVERAGE('WEB-02 Dashboard'!F6:F12) -> 0 | I26: Abrir →
B27: 21 | C27: WEB-03 Usuarios | D27: WEB-03 — Gestión de usuarios | E27: Web / Administrador | F27: =COUNTA('WEB-03 Usuarios'!B6:B11) -> 6 | G27: =COUNTA('WEB-03 Usuarios'!B17:B35) -> 19 | H27: =AVERAGE('WEB-03 Usuarios'!F6:F11) -> 0 | I27: Abrir →
B28: 22 | C28: WEB-04 Empresas | D28: WEB-04 — Empresas y validación | E28: Web / Administrador | F28: =COUNTA('WEB-04 Empresas'!B6:B11) -> 6 | G28: =COUNTA('WEB-04 Empresas'!B17:B34) -> 18 | H28: =AVERAGE('WEB-04 Empresas'!F6:F11) -> 0 | I28: Abrir →
B29: 23 | C29: WEB-05 Vacantes | D29: WEB-05 — Vacantes (moderación) | E29: Web / Administrador | F29: =COUNTA('WEB-05 Vacantes'!B6:B9) -> 4 | G29: =COUNTA('WEB-05 Vacantes'!B15:B28) -> 14 | H29: =AVERAGE('WEB-05 Vacantes'!F6:F9) -> 0 | I29: Abrir →
B30: 24 | C30: WEB-06 Categ. y habilidades | D30: WEB-06 — Categorías y habilidades | E30: Web / Administrador | F30: =COUNTA('WEB-06 Categ. y habilidades'!B6:B9) -> 4 | G30: =COUNTA('WEB-06 Categ. y habilidades'!B15:B28) -> 14 | H30: =AVERAGE('WEB-06 Categ. y habilidades'!F6:F9) -> 0 | I30: Abrir →
B31: 25 | C31: WEB-07 Catálogos | D31: WEB-07 — Catálogos | E31: Web / Administrador | F31: =COUNTA('WEB-07 Catálogos'!B6:B9) -> 4 | G31: =COUNTA('WEB-07 Catálogos'!B15:B28) -> 14 | H31: =AVERAGE('WEB-07 Catálogos'!F6:F9) -> 0 | I31: Abrir →
B32: 26 | C32: WEB-08 Reportes-incidencias | D32: WEB-08 — Reportes e incidencias | E32: Web / Administrador | F32: =COUNTA('WEB-08 Reportes-incidencias'!B6:B11) -> 6 | G32: =COUNTA('WEB-08 Reportes-incidencias'!B17:B34) -> 18 | H32: =AVERAGE('WEB-08 Reportes-incidencias'!F6:F11) -> 0 | I32: Abrir →
B33: 27 | C33: API | D33: API — FastAPI (objetivos del API) | E33: Backend | F33: =COUNTA(API!B6:B18) -> 13 | G33: =COUNTA(API!B24:B34) -> 11 | H33: =AVERAGE(API!F6:F18) -> 0 | I33: Abrir →
B34: Total | F34: =SUM(F7:F33) -> 156 | G34: =SUM(G7:G33) -> 443 | H34: =AVERAGE(H7:H33) -> 0
B37: Requerimientos No Funcionales generales (fuente de los RNF de cada hoja)
B38: # | C38: Hoja | D38: Grupo | E38: Aplica a | F38: # RNF | H38: Avance | I38: Ir
B39: 1 | C39: RNF Accesibilidad | D39: Accesibilidad (todas las interfaces móviles y web) | E39: MOV-*, CAN-*, REC-*, WEB-* | F39: =COUNTA('RNF Accesibilidad'!B6:B14) -> 9 | G39: — | H39: =AVERAGE('RNF Accesibilidad'!F6:F14) -> 0 | I39: Abrir →
B40: 2 | C40: RNF Autenticación | D40: Inicio de sesión, registro y recuperación | E40: MOV-01, MOV-02, MOV-03, WEB-01 | F40: =COUNTA('RNF Autenticación'!B6:B10) -> 5 | G40: — | H40: =AVERAGE('RNF Autenticación'!F6:F10) -> 0 | I40: Abrir →
B41: 3 | C41: RNF Privacidad | D41: Privacidad y datos sensibles | E41: MOV-02, CAN-02, CAN-03, CAN-04, REC-05, WEB-03, API | F41: =COUNTA('RNF Privacidad'!B6:B10) -> 5 | G41: — | H41: =AVERAGE('RNF Privacidad'!F6:F10) -> 0 | I41: Abrir →
B42: 4 | C42: RNF Operativas Móvil | D42: Pantallas móviles (compartidas, candidato y reclutador) | E42: MOV-*, CAN-*, REC-* | F42: =COUNTA('RNF Operativas Móvil'!B6:B10) -> 5 | G42: — | H42: =AVERAGE('RNF Operativas Móvil'!F6:F10) -> 0 | I42: Abrir →
B43: 5 | C43: RNF CRUD Web | D43: Pantallas de administración web | E43: WEB-03 a WEB-08 | F43: =COUNTA('RNF CRUD Web'!B6:B10) -> 5 | G43: — | H43: =AVERAGE('RNF CRUD Web'!F6:F10) -> 0 | I43: Abrir →
B44: 6 | C44: RNF Dashboard | D44: Dashboard y estadísticas | E44: WEB-02 | F44: =COUNTA('RNF Dashboard'!B6:B9) -> 4 | G44: — | H44: =AVERAGE('RNF Dashboard'!F6:F9) -> 0 | I44: Abrir →
...

Sheet MOV-00 Splash
B1: ← Índice
B3: Requerimientos Funcionales
B4: Interfaz : MOV-00 — Splash
B5: ID | C5: Requerimiento | D5: Descripción | E5: Prioridad | F5: Avance
B6: RF-01 | C6: Mostrar splash con logo | D6: Mostrar la pantalla inicial con el logotipo de IncluTec y un texto alternativo legible por lector de pantalla; duración máxima de 3 s. | E6: Alta | F6: 0
B7: RF-02 | C7: Verificar sesión persistente | D7: Validar el token almacenado contra GET /auth/me; si responde 200, redirigir a la pantalla principal del rol (CAN-01 o REC-02); si responde 401, redirigir a MOV-01. | E7: Alta | F7: 0
B10: Requerimientos No Funcionales
B11: Interfaz : MOV-00 — Splash · Accesibilidad, Pantallas móviles
B12: ID | C12: Nombre | D12: Descripción | E12: Prioridad | F12: Avance
B13: RNF-ACC-01 | C13: ='RNF Accesibilidad'!C6 -> Estándar de accesibilidad | D13: ='RNF Accesibilidad'!D6 -> Las interfaces cumplen las pautas WCAG 2.1 nivel AA. | E13: ='RNF Accesibilidad'!E6 -> Alta | F13: ='RNF Accesibilidad'!F6 -> 0
B14: RNF-ACC-02 | C14: ='RNF Accesibilidad'!C7 -> Lectores de pantalla | D14: ='RNF Accesibilidad'!D7 -> Todos los elementos interactivos tienen etiqueta, rol y estado accesibles (accessibilityLabel/Role/State en React Native; HTML semántico y ARIA en Laravel) y funcionan con TalkBack, VoiceOver y NVDA. | E14: ='RNF Accesibilidad'!E7 -> Alta | F14: ='RNF Accesibilidad'!F7 -> 0
B15: RNF-ACC-03 | C15: ='RNF Accesibilidad'!C8 -> Contraste | D15: ='RNF Accesibilidad'!D8 -> Contraste mínimo de 4.5:1 para texto normal y 3:1 para texto grande y componentes de interfaz. | E15: ='RNF Accesibilidad'!E8 -> Alta | F15: ='RNF Accesibilidad'!F8 -> 0
B16: RNF-ACC-04 | C16: ='RNF Accesibilidad'!C9 -> Texto escalable | D16: ='RNF Accesibilidad'!D9 -> La interfaz respeta el tamaño de fuente del sistema y admite hasta 200 % de ampliación sin pérdida de contenido ni funcionalidad. | E16: ='RNF Accesibilidad'!E9 -> Alta | F16: ='RNF Accesibilidad'!F9 -> 0
B17: RNF-ACC-05 | C17: ='RNF Accesibilidad'!C10 -> Áreas táctiles | D17: ='RNF Accesibilidad'!D10 -> Los componentes táctiles tienen un área mínima de 48 × 48 dp en Android y 44 × 44 pt en iOS. | E17: ='RNF Accesibilidad'!E10 -> Alta | F17: ='RNF Accesibilidad'!F10 -> 0
B18: RNF-ACC-06 | C18: ='RNF Accesibilidad'!C11 -> Información no dependiente del color | D18: ='RNF Accesibilidad'!D11 -> Estados, errores y porcentajes se comunican con texto o ícono además del color. | E18: ='RNF Accesibilidad'!E11 -> Alta | F18: ='RNF Accesibilidad'!F11 -> 0
B19: RNF-ACC-07 | C19: ='RNF Accesibilidad'!C12 -> Navegación por teclado | D19: ='RNF Accesibilidad'!D12 -> El panel web puede operarse completamente con teclado y la app admite teclado externo y control por interruptores (Switch Access / Control por botón), con foco visible y orden lógico. | E19: ='RNF Accesibilidad'!E12 -> Alta | F19: ='RNF Accesibilidad'!F12 -> 0
B20: RNF-ACC-08 | C20: ='RNF Accesibilidad'!C13 -> Lenguaje claro | D20: ='RNF Accesibilidad'!D13 -> Textos en lenguaje claro y sin tecnicismos; los errores de formulario indican qué campo falla y cómo corregirlo. | E20: ='RNF Accesibilidad'!E13 -> Media | F20: ='RNF Accesibilidad'!F13 -> 0
B21: RNF-ACC-09 | C21: ='RNF Accesibilidad'!C14 -> Movimiento reducido | D21: ='RNF Accesibilidad'!D14 -> Se respeta la preferencia de «reducir movimiento» del sistema y no hay contenido parpadeante. | E21: ='RNF Accesibilidad'!E14 -> Baja | F21: ='RNF Accesibilidad'!F14 -> 0
B22: RNF-MOV-01 | C22: ='RNF Operativas Móvil'!C6 -> Desempeño | D22: ='RNF Operativas Móvil'!D6 -> Tiempo de respuesta de las pantallas ≤ 2 s en el percentil 95 sobre red 4G. | E22: ='RNF Operativas Móvil'!E6 -> Alta | F22: ='RNF Operativas Móvil'!F6 -> 0
B23: RNF-MOV-02 | C23: ='RNF Operativas Móvil'!C7 -> Compatibilidad | D23: ='RNF Operativas Móvil'!D7 -> Ejecutable en Android 8+ e iOS 15+ con un solo código base (React Native + Expo). | E23: ='RNF Operativas Móvil'!E7 -> Alta | F23: ='RNF Operativas Móvil'!F7 -> 0
B24: RNF-MOV-03 | C24: ='RNF Operativas Móvil'!C8 -> Retroalimentación | D24: ='RNF Operativas Móvil'!D8 -> Toda acción que tarde más de 300 ms muestra un indicador de carga anunciado al lector de pantalla. | E24: ='RNF Operativas Móvil'!E8 -> Media | F24: ='RNF Operativas Móvil'!F8 -> 0
B25: RNF-MOV-04 | C25: ='RNF Operativas Móvil'!C9 -> Tolerancia a fallas de red | D25: ='RNF Operativas Móvil'!D9 -> La app conserva en caché el último listado de vacantes y postulaciones y avisa cuando no hay conexión; los formularios no pierden lo capturado. | E25: ='RNF Operativas Móvil'!E9 -> Media | F25: ='RNF Operativas Móvil'!F9 -> 0
B26: RNF-MOV-05 | C26: ='RNF Operativas Móvil'!C10 -> Orientación | D26: ='RNF Operativas Móvil'!D10 -> Las pantallas funcionan en orientación vertical y horizontal. | E26: ='RNF Operativas Móvil'!E10 -> Baja | F26: ='RNF Operativas Móvil'!F10 -> 0
B27: Los RNF provienen de las hojas generales «RNF …» y se actualizan automáticamente; edita el texto y el avance en su hoja general.
B30: Elaborado por: | C30: Alan David Santiago de Vicente, Ricardo Méndez Rodríguez, Eduardo Daniel Licea González
B31: Responsable: | C31: Equipo IncluTec — Ingeniería en Sistemas Computacionales
B32: Dependencias: | C32: API REST (FastAPI), Base de datos PostgreSQL
B33: Entrega: | C33: 28 de octubre de 2026
B36: Acotaciones de Avance
B37: 100% | C37: Completada
B38: 50% | C38: En proceso
B39: 0% | C39: No Iniciada
B42: Autorizado:

Sheet MOV-01 Login móvil
B1: ← Índice
B3: Requerimientos Funcionales
B4: Interfaz : MOV-01 — Inicio de sesión (móvil)
B5: ID | C5: Requerimiento | D5: Descripción | E5: Prioridad | F5: Avance
B6: RF-01 | C6: Captura de credenciales | D6: Capturar correo (formato RFC 5322) y contraseña (≥ 8 caracteres); el botón «Iniciar sesión» se habilita solo si ambos campos son válidos. Opción para mostrar u ocultar la contraseña. | E6: Alta | F6: 0
B7: RF-02 | C7: Autenticación contra API | D7: Enviar las credenciales a POST /auth/login; al recibir 200, almacenar el JWT en expo-secure-store. | E7: Alta | F7: 0
B8: RF-03 | C8: Manejo de errores | D8: Mostrar un mensaje específico ante 401 («Correo o contraseña incorrectos»), 423 («Cuenta suspendida») o 5xx («Servicio no disponible»), sin exponer detalles técnicos y anunciándolo al lector de pantalla. | E8: Alta | F8: 0
B9: RF-04 | C9: Redirección por rol | D9: Leer el rol del JWT y navegar a CAN-01 (candidato) o REC-02 (reclutador). Si el rol es «administrador», informar que debe usar el panel web y cerrar la sesión. | E9: Alta | F9: 0
B10: RF-05 | C10: Accesos secundarios | D10: Mostrar enlaces a MOV-02 (crear cuenta) y MOV-03 (recuperar contraseña). | E10: Media | F10: 0
B13: Requerimientos No Funcionales
B14: Interfaz : MOV-01 — Inicio de sesión (móvil) · Accesibilidad, Inicio de sesión, registro y recuperación, Pantallas móviles
B15: ID | C15: Nombre | D15: Descripción | E15: Prioridad | F15: Avance
B16: RNF-ACC-01 | C16: ='RNF Accesibilidad'!C6 -> Estándar de accesibilidad | D16: ='RNF Accesibilidad'!D6 -> Las interfaces cumplen las pautas WCAG 2.1 nivel AA. | E16: ='RNF Accesibilidad'!E6 -> Alta | F16: ='RNF Accesibilidad'!F6 -> 0
B17: RNF-ACC-02 | C17: ='RNF Accesibilidad'!C7 -> Lectores de pantalla | D17: ='RNF Accesibilidad'!D7 -> Todos los elementos interactivos tienen etiqueta, rol y estado accesibles (accessibilityLabel/Role/State en React Native; HTML semántico y ARIA en Laravel) y funcionan con TalkBack, VoiceOver y NVDA. | E17: ='RNF Accesibilidad'!E7 -> Alta | F17: ='RNF Accesibilidad'!F7 -> 0
B18: RNF-ACC-03 | C18: ='RNF Accesibilidad'!C8 -> Contraste | D18: ='RNF Accesibilidad'!D8 -> Contraste mínimo de 4.5:1 para texto normal y 3:1 para texto grande y componentes de interfaz. | E18: ='RNF Accesibilidad'!E8 -> Alta | F18: ='RNF Accesibilidad'!F8 -> 0
B19: RNF-ACC-04 | C19: ='RNF Accesibilidad'!C9 -> Texto escalable | D19: ='RNF Accesibilidad'!D9 -> La interfaz respeta el tamaño de fuente del sistema y admite hasta 200 % de ampliación sin pérdida de contenido ni funcionalidad. | E19: ='RNF Accesibilidad'!E9 -> Alta | F19: ='RNF Accesibilidad'!F9 -> 0
B20: RNF-ACC-05 | C20: ='RNF Accesibilidad'!C10 -> Áreas táctiles | D20: ='RNF Accesibilidad'!D10 -> Los componentes táctiles tienen un área mínima de 48 × 48 dp en Android y 44 × 44 pt en iOS. | E20: ='RNF Accesibilidad'!E10 -> Alta | F20: ='RNF Accesibilidad'!F10 -> 0
B21: RNF-ACC-06 | C21: ='RNF Accesibilidad'!C11 -> Información no dependiente del color | D21: ='RNF Accesibilidad'!D11 -> Estados, errores y porcentajes se comunican con texto o ícono además del color. | E21: ='RNF Accesibilidad'!E11 -> Alta | F21: ='RNF Accesibilidad'!F11 -> 0
B22: RNF-ACC-07 | C22: ='RNF Accesibilidad'!C12 -> Navegación por teclado | D22: ='RNF Accesibilidad'!D12 -> El panel web puede operarse completamente con teclado y la app admite teclado externo y control por interruptores (Switch Access / Control por botón), con foco visible y orden lógico. | E22: ='RNF Accesibilidad'!E12 -> Alta | F22: ='RNF Accesibilidad'!F12 -> 0
B23: RNF-ACC-08 | C23: ='RNF Accesibilidad'!C13 -> Lenguaje claro | D23: ='RNF Accesibilidad'!D13 -> Textos en lenguaje claro y sin tecnicismos; los errores de formulario indican qué campo falla y cómo corregirlo. | E23: ='RNF Accesibilidad'!E13 -> Media | F23: ='RNF Accesibilidad'!F13 -> 0
B24: RNF-ACC-09 | C24: ='RNF Accesibilidad'!C14 -> Movimiento reducido | D24: ='RNF Accesibilidad'!D14 -> Se respeta la preferencia de «reducir movimiento» del sistema y no hay contenido parpadeante. | E24: ='RNF Accesibilidad'!E14 -> Baja | F24: ='RNF Accesibilidad'!F14 -> 0
B25: RNF-AUT-01 | C25: ='RNF Autenticación'!C6 -> Seguridad — contraseñas | D25: ='RNF Autenticación'!D6 -> Las contraseñas se almacenan únicamente como hash bcrypt (cost ≥ 10); nunca en texto plano ni en registros. | E25: ='RNF Autenticación'!E6 -> Alta | F25: ='RNF Autenticación'!F6 -> 0
B26: RNF-AUT-02 | C26: ='RNF Autenticación'!C7 -> Seguridad — tokens | D26: ='RNF Autenticación'!D7 -> JWT firmado HS256 con expiración de 8 h; transporte HTTPS obligatorio; almacenamiento en expo-secure-store (móvil) y en la sesión del servidor Laravel (web). | E26: ='RNF Autenticación'!E7 -> Alta | F26: ='RNF Autenticación'!F7 -> 0
B27: RNF-AUT-03 | C27: ='RNF Autenticación'!C8 -> Protección contra fuerza bruta | D27: ='RNF Autenticación'!D8 -> Bloqueo temporal de 15 minutos tras 5 intentos fallidos consecutivos por cuenta o por IP. | E27: ='RNF Autenticación'!E8 -> Alta | F27: ='RNF Autenticación'!F8 -> 0
B28: RNF-AUT-04 | C28: ='RNF Autenticación'!C9 -> Mensajes neutros | D28: ='RNF Autenticación'!D9 -> Los mensajes de error no revelan si un correo existe en el sistema. | E28: ='RNF Autenticación'!E9 -> Media | F28: ='RNF Autenticación'!F9 -> 0
B29: RNF-AUT-05 | C29: ='RNF Autenticación'!C10 -> Desempeño | D29: ='RNF Autenticación'!D10 -> El inicio de sesión responde en ≤ 1.5 s en el percentil 95. | E29: ='RNF Autenticación'!E10 -> Media | F29: ='RNF Autenticación'!F10 -> 0
B30: RNF-MOV-01 | C30: ='RNF Operativas Móvil'!C6 -> Desempeño | D30: ='RNF Operativas Móvil'!D6 -> Tiempo de respuesta de las pantallas ≤ 2 s en el percentil 95 sobre red 4G. | E30: ='RNF Operativas Móvil'!E6 -> Alta | F30: ='RNF Operativas Móvil'!F6 -> 0
B31: RNF-MOV-02 | C31: ='RNF Operativas Móvil'!C7 -> Compatibilidad | D31: ='RNF Operativas Móvil'!D7 -> Ejecutable en Android 8+ e iOS 15+ con un solo código base (React Native + Expo). | E31: ='RNF Operativas Móvil'!E7 -> Alta | F31: ='RNF Operativas Móvil'!F7 -> 0
B32: RNF-MOV-03 | C32: ='RNF Operativas Móvil'!C8 -> Retroalimentación | D32: ='RNF Operativas Móvil'!D8 -> Toda acción que tarde más de 300 ms muestra un indicador de carga anunciado al lector de pantalla. | E32: ='RNF Operativas Móvil'!E8 -> Media | F32: ='RNF Operativas Móvil'!F8 -> 0
B33: RNF-MOV-04 | C33: ='RNF Operativas Móvil'!C9 -> Tolerancia a fallas de red | D33: ='RNF Operativas Móvil'!D9 -> La app conserva en caché el último listado de vacantes y postulaciones y avisa cuando no hay conexión; los formularios no pierden lo capturado. | E33: ='RNF Operativas Móvil'!E9 -> Media | F33: ='RNF Operativas Móvil'!F9 -> 0
B34: RNF-MOV-05 | C34: ='RNF Operativas Móvil'!C10 -> Orientación | D34: ='RNF Operativas Móvil'!D10 -> Las pantallas funcionan en orientación vertical y horizontal. | E34: ='RNF Operativas Móvil'!E10 -> Baja | F34: ='RNF Operativas Móvil'!F10 -> 0
B35: Los RNF provienen de las hojas generales «RNF …» y se actualizan automáticamente; edita el texto y el avance en su hoja general.
B38: Elaborado por: | C38: Alan David Santiago de Vicente, Ricardo Méndez Rodríguez, Eduardo Daniel Licea González
B39: Responsable: | C39: Equipo IncluTec — Ingeniería en Sistemas Computacionales
B40: Dependencias: | C40: API REST (FastAPI), Base de datos PostgreSQL
B41: Entrega: | C41: 28 de octubre de 2026
B44: Acotaciones de Avance
B45: 100% | C45: Completada
B46: 50% | C46: En proceso
B47: 0% | C47: No Iniciada
...

Sheet MOV-02 Registro
B1: ← Índice
B3: Requerimientos Funcionales
B4: Interfaz : MOV-02 — Registro de cuenta
B5: ID | C5: Requerimiento | D5: Descripción | E5: Prioridad | F5: Avance
B6: RF-01 | C6: Selección de tipo de cuenta | D6: Permitir elegir entre «Busco empleo» (candidato) y «Represento a una empresa» (reclutador) antes de mostrar el formulario correspondiente. | E6: Alta | F6: 0
B7: RF-02 | C7: Registro de candidato | D7: Capturar nombre(s), apellidos, correo, teléfono (10 dígitos), municipio/estado y contraseña; enviar a POST /auth/registro/candidato. | E7: Alta | F7: 0
B8: RF-03 | C8: Registro de reclutador y empresa | D8: Capturar datos del reclutador (nombre, puesto, correo, teléfono, contraseña) y de la empresa (razón social, nombre comercial, RFC de 12 o 13 caracteres, sector, tamaño, municipio/estado); enviar a POST /auth/registro/reclutador. La empresa se crea en estado «pendiente de validación». | E8: Alta | F8: 0
B9: RF-04 | C9: Política de contraseña | D9: Validar contraseña de 8 a 64 caracteres con al menos una letra y un número, y confirmar que ambas capturas coincidan. | E9: Alta | F9: 0
B10: RF-05 | C10: Aviso de privacidad y consentimiento | D10: Mostrar el aviso de privacidad y exigir su aceptación. Para candidatos, solicitar además el consentimiento expreso para el tratamiento de datos sobre necesidades de ajuste (dato personal sensible, LFPDPPP); sin él, la cuenta se crea pero esa sección queda deshabilitada. | E10: Alta | F10: 0
B11: RF-06 | C11: Unicidad de correo | D11: Si el API responde 409, indicar que el correo ya está registrado y ofrecer ir a MOV-01 o MOV-03. | E11: Media | F11: 0
B12: RF-07 | C12: Inicio tras registro | D12: Al recibir 201, iniciar sesión automáticamente y dirigir al candidato a CAN-03 (completar perfil) y al reclutador a REC-01 (perfil de la organización). | E12: Media | F12: 0
B15: Requerimientos No Funcionales
B16: Interfaz : MOV-02 — Registro de cuenta · Accesibilidad, Inicio de sesión, registro y recuperación, Privacidad y datos sensibles, Pantallas móviles
B17: ID | C17: Nombre | D17: Descripción | E17: Prioridad | F17: Avance
B18: RNF-ACC-01 | C18: ='RNF Accesibilidad'!C6 -> Estándar de accesibilidad | D18: ='RNF Accesibilidad'!D6 -> Las interfaces cumplen las pautas WCAG 2.1 nivel AA. | E18: ='RNF Accesibilidad'!E6 -> Alta | F18: ='RNF Accesibilidad'!F6 -> 0
B19: RNF-ACC-02 | C19: ='RNF Accesibilidad'!C7 -> Lectores de pantalla | D19: ='RNF Accesibilidad'!D7 -> Todos los elementos interactivos tienen etiqueta, rol y estado accesibles (accessibilityLabel/Role/State en React Native; HTML semántico y ARIA en Laravel) y funcionan con TalkBack, VoiceOver y NVDA. | E19: ='RNF Accesibilidad'!E7 -> Alta | F19: ='RNF Accesibilidad'!F7 -> 0
B20: RNF-ACC-03 | C20: ='RNF Accesibilidad'!C8 -> Contraste | D20: ='RNF Accesibilidad'!D8 -> Contraste mínimo de 4.5:1 para texto normal y 3:1 para texto grande y componentes de interfaz. | E20: ='RNF Accesibilidad'!E8 -> Alta | F20: ='RNF Accesibilidad'!F8 -> 0
B21: RNF-ACC-04 | C21: ='RNF Accesibilidad'!C9 -> Texto escalable | D21: ='RNF Accesibilidad'!D9 -> La interfaz respeta el tamaño de fuente del sistema y admite hasta 200 % de ampliación sin pérdida de contenido ni funcionalidad. | E21: ='RNF Accesibilidad'!E9 -> Alta | F21: ='RNF Accesibilidad'!F9 -> 0
B22: RNF-ACC-05 | C22: ='RNF Accesibilidad'!C10 -> Áreas táctiles | D22: ='RNF Accesibilidad'!D10 -> Los componentes táctiles tienen un área mínima de 48 × 48 dp en Android y 44 × 44 pt en iOS. | E22: ='RNF Accesibilidad'!E10 -> Alta | F22: ='RNF Accesibilidad'!F10 -> 0
B23: RNF-ACC-06 | C23: ='RNF Accesibilidad'!C11 -> Información no dependiente del color | D23: ='RNF Accesibilidad'!D11 -> Estados, errores y porcentajes se comunican con texto o ícono además del color. | E23: ='RNF Accesibilidad'!E11 -> Alta | F23: ='RNF Accesibilidad'!F11 -> 0
B24: RNF-ACC-07 | C24: ='RNF Accesibilidad'!C12 -> Navegación por teclado | D24: ='RNF Accesibilidad'!D12 -> El panel web puede operarse completamente con teclado y la app admite teclado externo y control por interruptores (Switch Access / Control por botón), con foco visible y orden lógico. | E24: ='RNF Accesibilidad'!E12 -> Alta | F24: ='RNF Accesibilidad'!F12 -> 0
B25: RNF-ACC-08 | C25: ='RNF Accesibilidad'!C13 -> Lenguaje claro | D25: ='RNF Accesibilidad'!D13 -> Textos en lenguaje claro y sin tecnicismos; los errores de formulario indican qué campo falla y cómo corregirlo. | E25: ='RNF Accesibilidad'!E13 -> Media | F25: ='RNF Accesibilidad'!F13 -> 0
B26: RNF-ACC-09 | C26: ='RNF Accesibilidad'!C14 -> Movimiento reducido | D26: ='RNF Accesibilidad'!D14 -> Se respeta la preferencia de «reducir movimiento» del sistema y no hay contenido parpadeante. | E26: ='RNF Accesibilidad'!E14 -> Baja | F26: ='RNF Accesibilidad'!F14 -> 0
B27: RNF-AUT-01 | C27: ='RNF Autenticación'!C6 -> Seguridad — contraseñas | D27: ='RNF Autenticación'!D6 -> Las contraseñas se almacenan únicamente como hash bcrypt (cost ≥ 10); nunca en texto plano ni en registros. | E27: ='RNF Autenticación'!E6 -> Alta | F27: ='RNF Autenticación'!F6 -> 0
B28: RNF-AUT-02 | C28: ='RNF Autenticación'!C7 -> Seguridad — tokens | D28: ='RNF Autenticación'!D7 -> JWT firmado HS256 con expiración de 8 h; transporte HTTPS obligatorio; almacenamiento en expo-secure-store (móvil) y en la sesión del servidor Laravel (web). | E28: ='RNF Autenticación'!E7 -> Alta | F28: ='RNF Autenticación'!F7 -> 0
B29: RNF-AUT-03 | C29: ='RNF Autenticación'!C8 -> Protección contra fuerza bruta | D29: ='RNF Autenticación'!D8 -> Bloqueo temporal de 15 minutos tras 5 intentos fallidos consecutivos por cuenta o por IP. | E29: ='RNF Autenticación'!E8 -> Alta | F29: ='RNF Autenticación'!F8 -> 0
B30: RNF-AUT-04 | C30: ='RNF Autenticación'!C9 -> Mensajes neutros | D30: ='RNF Autenticación'!D9 -> Los mensajes de error no revelan si un correo existe en el sistema. | E30: ='RNF Autenticación'!E9 -> Media | F30: ='RNF Autenticación'!F9 -> 0
B31: RNF-AUT-05 | C31: ='RNF Autenticación'!C10 -> Desempeño | D31: ='RNF Autenticación'!D10 -> El inicio de sesión responde en ≤ 1.5 s en el percentil 95. | E31: ='RNF Autenticación'!E10 -> Media | F31: ='RNF Autenticación'!F10 -> 0
B32: RNF-PRV-01 | C32: ='RNF Privacidad'!C6 -> Cumplimiento legal | D32: ='RNF Privacidad'!D6 -> El tratamiento de datos personales cumple la Ley Federal de Protección de Datos Personales en Posesión de los Particulares, con aviso de privacidad y consentimiento expreso para datos sensibles. | E32: ='RNF Privacidad'!E6 -> Alta | F32: ='RNF Privacidad'!F6 -> 0
B33: RNF-PRV-02 | C33: ='RNF Privacidad'!C7 -> Minimización de datos | D33: ='RNF Privacidad'!D7 -> El sistema registra necesidades de ajuste y no diagnósticos, tipos de discapacidad ni documentos médicos. | E33: ='RNF Privacidad'!E7 -> Alta | F33: ='RNF Privacidad'!F7 -> 0
B34: RNF-PRV-03 | C34: ='RNF Privacidad'!C8 -> Control del candidato | D34: ='RNF Privacidad'!D8 -> Las necesidades de ajuste solo son visibles para el candidato y para las empresas a cuyas vacantes se postuló con consentimiento; el administrador solo ve datos agregados. | E34: ='RNF Privacidad'!E8 -> Alta | F34: ='RNF Privacidad'!F8 -> 0
B35: RNF-PRV-04 | C35: ='RNF Privacidad'!C9 -> Derechos ARCO | D35: ='RNF Privacidad'!D9 -> El candidato puede consultar, corregir y eliminar sus datos; la eliminación anonimiza sus postulaciones históricas en un plazo máximo de 30 días. | E35: ='RNF Privacidad'!E9 -> Alta | F35: ='RNF Privacidad'!F9 -> 0
B36: RNF-PRV-05 | C36: ='RNF Privacidad'!C10 -> Registros sin datos sensibles | D36: ='RNF Privacidad'!D10 -> Los logs del servidor y los mensajes push no incluyen necesidades de ajuste ni datos de contacto. | E36: ='RNF Privacidad'!E10 -> Alta | F36: ='RNF Privacidad'!F10 -> 0
B37: RNF-MOV-01 | C37: ='RNF Operativas Móvil'!C6 -> Desempeño | D37: ='RNF Operativas Móvil'!D6 -> Tiempo de respuesta de las pantallas ≤ 2 s en el percentil 95 sobre red 4G. | E37: ='RNF Operativas Móvil'!E6 -> Alta | F37: ='RNF Operativas Móvil'!F6 -> 0
B38: RNF-MOV-02 | C38: ='RNF Operativas Móvil'!C7 -> Compatibilidad | D38: ='RNF Operativas Móvil'!D7 -> Ejecutable en Android 8+ e iOS 15+ con un solo código base (React Native + Expo). | E38: ='RNF Operativas Móvil'!E7 -> Alta | F38: ='RNF Operativas Móvil'!F7 -> 0
B39: RNF-MOV-03 | C39: ='RNF Operativas Móvil'!C8 -> Retroalimentación | D39: ='RNF Operativas Móvil'!D8 -> Toda acción que tarde más de 300 ms muestra un indicador de carga anunciado al lector de pantalla. | E39: ='RNF Operativas Móvil'!E8 -> Media | F39: ='RNF Operativas Móvil'!F8 -> 0
B40: RNF-MOV-04 | C40: ='RNF Operativas Móvil'!C9 -> Tolerancia a fallas de red | D40: ='RNF Operativas Móvil'!D9 -> La app conserva en caché el último listado de vacantes y postulaciones y avisa cuando no hay conexión; los formularios no pierden lo capturado. | E40: ='RNF Operativas Móvil'!E9 -> Media | F40: ='RNF Operativas Móvil'!F9 -> 0
B41: RNF-MOV-05 | C41: ='RNF Operativas Móvil'!C10 -> Orientación | D41: ='RNF Operativas Móvil'!D10 -> Las pantallas funcionan en orientación vertical y horizontal. | E41: ='RNF Operativas Móvil'!E10 -> Baja | F41: ='RNF Operativas Móvil'!F10 -> 0
B42: Los RNF provienen de las hojas generales «RNF …» y se actualizan automáticamente; edita el texto y el avance en su hoja general.
B45: Elaborado por: | C45: Alan David Santiago de Vicente, Ricardo Méndez Rodríguez, Eduardo Daniel Licea González
...

Sheet MOV-03 Recuperar contraseña
B1: ← Índice
B3: Requerimientos Funcionales
B4: Interfaz : MOV-03 — Recuperar contraseña
B5: ID | C5: Requerimiento | D5: Descripción | E5: Prioridad | F5: Avance
B6: RF-01 | C6: Solicitud de código | D6: Capturar el correo y enviarlo a POST /auth/password/solicitar; mostrar siempre el mismo mensaje de confirmación, exista o no la cuenta. | E6: Alta | F6: 0
B7: RF-02 | C7: Validación de código | D7: Capturar el código de 6 dígitos recibido por correo; el código vence a los 15 minutos y admite máximo 5 intentos. | E7: Alta | F7: 0
B8: RF-03 | C8: Nueva contraseña | D8: Capturar y confirmar la nueva contraseña (misma política que MOV-02) y enviarla a POST /auth/password/restablecer; al recibir 200, regresar a MOV-01 con mensaje de éxito. | E8: Alta | F8: 0
B9: RF-04 | C9: Reenvío de código | D9: Permitir reenviar el código una vez transcurridos 60 s desde el envío anterior. | E9: Baja | F9: 0
B12: Requerimientos No Funcionales
B13: Interfaz : MOV-03 — Recuperar contraseña · Accesibilidad, Inicio de sesión, registro y recuperación, Pantallas móviles
B14: ID | C14: Nombre | D14: Descripción | E14: Prioridad | F14: Avance
B15: RNF-ACC-01 | C15: ='RNF Accesibilidad'!C6 -> Estándar de accesibilidad | D15: ='RNF Accesibilidad'!D6 -> Las interfaces cumplen las pautas WCAG 2.1 nivel AA. | E15: ='RNF Accesibilidad'!E6 -> Alta | F15: ='RNF Accesibilidad'!F6 -> 0
B16: RNF-ACC-02 | C16: ='RNF Accesibilidad'!C7 -> Lectores de pantalla | D16: ='RNF Accesibilidad'!D7 -> Todos los elementos interactivos tienen etiqueta, rol y estado accesibles (accessibilityLabel/Role/State en React Native; HTML semántico y ARIA en Laravel) y funcionan con TalkBack, VoiceOver y NVDA. | E16: ='RNF Accesibilidad'!E7 -> Alta | F16: ='RNF Accesibilidad'!F7 -> 0
B17: RNF-ACC-03 | C17: ='RNF Accesibilidad'!C8 -> Contraste | D17: ='RNF Accesibilidad'!D8 -> Contraste mínimo de 4.5:1 para texto normal y 3:1 para texto grande y componentes de interfaz. | E17: ='RNF Accesibilidad'!E8 -> Alta | F17: ='RNF Accesibilidad'!F8 -> 0
B18: RNF-ACC-04 | C18: ='RNF Accesibilidad'!C9 -> Texto escalable | D18: ='RNF Accesibilidad'!D9 -> La interfaz respeta el tamaño de fuente del sistema y admite hasta 200 % de ampliación sin pérdida de contenido ni funcionalidad. | E18: ='RNF Accesibilidad'!E9 -> Alta | F18: ='RNF Accesibilidad'!F9 -> 0
B19: RNF-ACC-05 | C19: ='RNF Accesibilidad'!C10 -> Áreas táctiles | D19: ='RNF Accesibilidad'!D10 -> Los componentes táctiles tienen un área mínima de 48 × 48 dp en Android y 44 × 44 pt en iOS. | E19: ='RNF Accesibilidad'!E10 -> Alta | F19: ='RNF Accesibilidad'!F10 -> 0
B20: RNF-ACC-06 | C20: ='RNF Accesibilidad'!C11 -> Información no dependiente del color | D20: ='RNF Accesibilidad'!D11 -> Estados, errores y porcentajes se comunican con texto o ícono además del color. | E20: ='RNF Accesibilidad'!E11 -> Alta | F20: ='RNF Accesibilidad'!F11 -> 0
B21: RNF-ACC-07 | C21: ='RNF Accesibilidad'!C12 -> Navegación por teclado | D21: ='RNF Accesibilidad'!D12 -> El panel web puede operarse completamente con teclado y la app admite teclado externo y control por interruptores (Switch Access / Control por botón), con foco visible y orden lógico. | E21: ='RNF Accesibilidad'!E12 -> Alta | F21: ='RNF Accesibilidad'!F12 -> 0
B22: RNF-ACC-08 | C22: ='RNF Accesibilidad'!C13 -> Lenguaje claro | D22: ='RNF Accesibilidad'!D13 -> Textos en lenguaje claro y sin tecnicismos; los errores de formulario indican qué campo falla y cómo corregirlo. | E22: ='RNF Accesibilidad'!E13 -> Media | F22: ='RNF Accesibilidad'!F13 -> 0
B23: RNF-ACC-09 | C23: ='RNF Accesibilidad'!C14 -> Movimiento reducido | D23: ='RNF Accesibilidad'!D14 -> Se respeta la preferencia de «reducir movimiento» del sistema y no hay contenido parpadeante. | E23: ='RNF Accesibilidad'!E14 -> Baja | F23: ='RNF Accesibilidad'!F14 -> 0
B24: RNF-AUT-01 | C24: ='RNF Autenticación'!C6 -> Seguridad — contraseñas | D24: ='RNF Autenticación'!D6 -> Las contraseñas se almacenan únicamente como hash bcrypt (cost ≥ 10); nunca en texto plano ni en registros. | E24: ='RNF Autenticación'!E6 -> Alta | F24: ='RNF Autenticación'!F6 -> 0
B25: RNF-AUT-02 | C25: ='RNF Autenticación'!C7 -> Seguridad — tokens | D25: ='RNF Autenticación'!D7 -> JWT firmado HS256 con expiración de 8 h; transporte HTTPS obligatorio; almacenamiento en expo-secure-store (móvil) y en la sesión del servidor Laravel (web). | E25: ='RNF Autenticación'!E7 -> Alta | F25: ='RNF Autenticación'!F7 -> 0
B26: RNF-AUT-03 | C26: ='RNF Autenticación'!C8 -> Protección contra fuerza bruta | D26: ='RNF Autenticación'!D8 -> Bloqueo temporal de 15 minutos tras 5 intentos fallidos consecutivos por cuenta o por IP. | E26: ='RNF Autenticación'!E8 -> Alta | F26: ='RNF Autenticación'!F8 -> 0
B27: RNF-AUT-04 | C27: ='RNF Autenticación'!C9 -> Mensajes neutros | D27: ='RNF Autenticación'!D9 -> Los mensajes de error no revelan si un correo existe en el sistema. | E27: ='RNF Autenticación'!E9 -> Media | F27: ='RNF Autenticación'!F9 -> 0
B28: RNF-AUT-05 | C28: ='RNF Autenticación'!C10 -> Desempeño | D28: ='RNF Autenticación'!D10 -> El inicio de sesión responde en ≤ 1.5 s en el percentil 95. | E28: ='RNF Autenticación'!E10 -> Media | F28: ='RNF Autenticación'!F10 -> 0
B29: RNF-MOV-01 | C29: ='RNF Operativas Móvil'!C6 -> Desempeño | D29: ='RNF Operativas Móvil'!D6 -> Tiempo de respuesta de las pantallas ≤ 2 s en el percentil 95 sobre red 4G. | E29: ='RNF Operativas Móvil'!E6 -> Alta | F29: ='RNF Operativas Móvil'!F6 -> 0
B30: RNF-MOV-02 | C30: ='RNF Operativas Móvil'!C7 -> Compatibilidad | D30: ='RNF Operativas Móvil'!D7 -> Ejecutable en Android 8+ e iOS 15+ con un solo código base (React Native + Expo). | E30: ='RNF Operativas Móvil'!E7 -> Alta | F30: ='RNF Operativas Móvil'!F7 -> 0
B31: RNF-MOV-03 | C31: ='RNF Operativas Móvil'!C8 -> Retroalimentación | D31: ='RNF Operativas Móvil'!D8 -> Toda acción que tarde más de 300 ms muestra un indicador de carga anunciado al lector de pantalla. | E31: ='RNF Operativas Móvil'!E8 -> Media | F31: ='RNF Operativas Móvil'!F8 -> 0
B32: RNF-MOV-04 | C32: ='RNF Operativas Móvil'!C9 -> Tolerancia a fallas de red | D32: ='RNF Operativas Móvil'!D9 -> La app conserva en caché el último listado de vacantes y postulaciones y avisa cuando no hay conexión; los formularios no pierden lo capturado. | E32: ='RNF Operativas Móvil'!E9 -> Media | F32: ='RNF Operativas Móvil'!F9 -> 0
B33: RNF-MOV-05 | C33: ='RNF Operativas Móvil'!C10 -> Orientación | D33: ='RNF Operativas Móvil'!D10 -> Las pantallas funcionan en orientación vertical y horizontal. | E33: ='RNF Operativas Móvil'!E10 -> Baja | F33: ='RNF Operativas Móvil'!F10 -> 0
B34: Los RNF provienen de las hojas generales «RNF …» y se actualizan automáticamente; edita el texto y el avance en su hoja general.
B37: Elaborado por: | C37: Alan David Santiago de Vicente, Ricardo Méndez Rodríguez, Eduardo Daniel Licea González
B38: Responsable: | C38: Equipo IncluTec — Ingeniería en Sistemas Computacionales
B39: Dependencias: | C39: API REST (FastAPI), Base de datos PostgreSQL; servicio de correo (SMTP)
B40: Entrega: | C40: 28 de octubre de 2026
B43: Acotaciones de Avance
B44: 100% | C44: Completada
B45: 50% | C45: En proceso
B46: 0% | C46: No Iniciada
B49: Autorizado:

Sheet MOV-04 Notificaciones
B1: ← Índice
B3: Requerimientos Funcionales
B4: Interfaz : MOV-04 — Notificaciones
B5: ID | C5: Requerimiento | D5: Descripción | E5: Prioridad | F5: Avance
B6: RF-01 | C6: Registro del dispositivo | D6: Al iniciar sesión, solicitar permiso de notificaciones y registrar el token con POST /dispositivos. | E6: Alta | F6: 0
B7: RF-02 | C7: Listado de notificaciones | D7: Listar las notificaciones del usuario vía GET /notificaciones (paginado de 20, más recientes primero) con título, mensaje, fecha y estado leída/no leída. | E7: Alta | F7: 0
B8: RF-03 | C8: Indicador de no leídas | D8: Mostrar en la barra de navegación un contador de notificaciones no leídas, anunciado por el lector de pantalla (p. ej. «Notificaciones, 3 sin leer»). | E8: Media | F8: 0
B9: RF-04 | C9: Marcar como leída | D9: Marcar una notificación como leída al abrirla (PATCH /notificaciones/{id}/leida) y permitir marcar todas (PATCH /notificaciones/leidas). | E9: Media | F9: 0
B10: RF-05 | C10: Navegación al origen | D10: Al tocar una notificación, abrir la pantalla relacionada (CAN-06, REC-05, REC-06 o REC-01) con el identificador correspondiente. | E10: Media | F10: 0
B11: RF-06 | C11: Preferencias de canal | D11: Permitir activar o desactivar el aviso por push y por correo para cada tipo de evento vía PUT /notificaciones/preferencias. | E11: Baja | F11: 0
B14: Requerimientos No Funcionales
B15: Interfaz : MOV-04 — Notificaciones · Accesibilidad, Pantallas móviles, Notificaciones
B16: ID | C16: Nombre | D16: Descripción | E16: Prioridad | F16: Avance
B17: RNF-ACC-01 | C17: ='RNF Accesibilidad'!C6 -> Estándar de accesibilidad | D17: ='RNF Accesibilidad'!D6 -> Las interfaces cumplen las pautas WCAG 2.1 nivel AA. | E17: ='RNF Accesibilidad'!E6 -> Alta | F17: ='RNF Accesibilidad'!F6 -> 0
B18: RNF-ACC-02 | C18: ='RNF Accesibilidad'!C7 -> Lectores de pantalla | D18: ='RNF Accesibilidad'!D7 -> Todos los elementos interactivos tienen etiqueta, rol y estado accesibles (accessibilityLabel/Role/State en React Native; HTML semántico y ARIA en Laravel) y funcionan con TalkBack, VoiceOver y NVDA. | E18: ='RNF Accesibilidad'!E7 -> Alta | F18: ='RNF Accesibilidad'!F7 -> 0
B19: RNF-ACC-03 | C19: ='RNF Accesibilidad'!C8 -> Contraste | D19: ='RNF Accesibilidad'!D8 -> Contraste mínimo de 4.5:1 para texto normal y 3:1 para texto grande y componentes de interfaz. | E19: ='RNF Accesibilidad'!E8 -> Alta | F19: ='RNF Accesibilidad'!F8 -> 0
B20: RNF-ACC-04 | C20: ='RNF Accesibilidad'!C9 -> Texto escalable | D20: ='RNF Accesibilidad'!D9 -> La interfaz respeta el tamaño de fuente del sistema y admite hasta 200 % de ampliación sin pérdida de contenido ni funcionalidad. | E20: ='RNF Accesibilidad'!E9 -> Alta | F20: ='RNF Accesibilidad'!F9 -> 0
B21: RNF-ACC-05 | C21: ='RNF Accesibilidad'!C10 -> Áreas táctiles | D21: ='RNF Accesibilidad'!D10 -> Los componentes táctiles tienen un área mínima de 48 × 48 dp en Android y 44 × 44 pt en iOS. | E21: ='RNF Accesibilidad'!E10 -> Alta | F21: ='RNF Accesibilidad'!F10 -> 0
B22: RNF-ACC-06 | C22: ='RNF Accesibilidad'!C11 -> Información no dependiente del color | D22: ='RNF Accesibilidad'!D11 -> Estados, errores y porcentajes se comunican con texto o ícono además del color. | E22: ='RNF Accesibilidad'!E11 -> Alta | F22: ='RNF Accesibilidad'!F11 -> 0
B23: RNF-ACC-07 | C23: ='RNF Accesibilidad'!C12 -> Navegación por teclado | D23: ='RNF Accesibilidad'!D12 -> El panel web puede operarse completamente con teclado y la app admite teclado externo y control por interruptores (Switch Access / Control por botón), con foco visible y orden lógico. | E23: ='RNF Accesibilidad'!E12 -> Alta | F23: ='RNF Accesibilidad'!F12 -> 0
B24: RNF-ACC-08 | C24: ='RNF Accesibilidad'!C13 -> Lenguaje claro | D24: ='RNF Accesibilidad'!D13 -> Textos en lenguaje claro y sin tecnicismos; los errores de formulario indican qué campo falla y cómo corregirlo. | E24: ='RNF Accesibilidad'!E13 -> Media | F24: ='RNF Accesibilidad'!F13 -> 0
B25: RNF-ACC-09 | C25: ='RNF Accesibilidad'!C14 -> Movimiento reducido | D25: ='RNF Accesibilidad'!D14 -> Se respeta la preferencia de «reducir movimiento» del sistema y no hay contenido parpadeante. | E25: ='RNF Accesibilidad'!E14 -> Baja | F25: ='RNF Accesibilidad'!F14 -> 0
B26: RNF-MOV-01 | C26: ='RNF Operativas Móvil'!C6 -> Desempeño | D26: ='RNF Operativas Móvil'!D6 -> Tiempo de respuesta de las pantallas ≤ 2 s en el percentil 95 sobre red 4G. | E26: ='RNF Operativas Móvil'!E6 -> Alta | F26: ='RNF Operativas Móvil'!F6 -> 0
B27: RNF-MOV-02 | C27: ='RNF Operativas Móvil'!C7 -> Compatibilidad | D27: ='RNF Operativas Móvil'!D7 -> Ejecutable en Android 8+ e iOS 15+ con un solo código base (React Native + Expo). | E27: ='RNF Operativas Móvil'!E7 -> Alta | F27: ='RNF Operativas Móvil'!F7 -> 0
B28: RNF-MOV-03 | C28: ='RNF Operativas Móvil'!C8 -> Retroalimentación | D28: ='RNF Operativas Móvil'!D8 -> Toda acción que tarde más de 300 ms muestra un indicador de carga anunciado al lector de pantalla. | E28: ='RNF Operativas Móvil'!E8 -> Media | F28: ='RNF Operativas Móvil'!F8 -> 0
B29: RNF-MOV-04 | C29: ='RNF Operativas Móvil'!C9 -> Tolerancia a fallas de red | D29: ='RNF Operativas Móvil'!D9 -> La app conserva en caché el último listado de vacantes y postulaciones y avisa cuando no hay conexión; los formularios no pierden lo capturado. | E29: ='RNF Operativas Móvil'!E9 -> Media | F29: ='RNF Operativas Móvil'!F9 -> 0
B30: RNF-MOV-05 | C30: ='RNF Operativas Móvil'!C10 -> Orientación | D30: ='RNF Operativas Móvil'!D10 -> Las pantallas funcionan en orientación vertical y horizontal. | E30: ='RNF Operativas Móvil'!E10 -> Baja | F30: ='RNF Operativas Móvil'!F10 -> 0
B31: RNF-NOT-01 | C31: ='RNF Notificaciones'!C6 -> Tiempo de entrega | D31: ='RNF Notificaciones'!D6 -> Las notificaciones push se envían en ≤ 1 min y los correos en ≤ 5 min tras el evento. | E31: ='RNF Notificaciones'!E6 -> Media | F31: ='RNF Notificaciones'!F6 -> 0
B32: RNF-NOT-02 | C32: ='RNF Notificaciones'!C7 -> Confiabilidad | D32: ='RNF Notificaciones'!D7 -> Los envíos fallidos se reintentan hasta 3 veces; el fallo de un canal no bloquea la operación que lo generó. | E32: ='RNF Notificaciones'!E7 -> Alta | F32: ='RNF Notificaciones'!F7 -> 0
B33: RNF-NOT-03 | C33: ='RNF Notificaciones'!C8 -> Correos accesibles | D33: ='RNF Notificaciones'!D8 -> Los correos incluyen versión en texto plano, estructura semántica y enlaces descriptivos. | E33: ='RNF Notificaciones'!E8 -> Media | F33: ='RNF Notificaciones'!F8 -> 0
B34: RNF-NOT-04 | C34: ='RNF Notificaciones'!C9 -> Contenido mínimo | D34: ='RNF Notificaciones'!D9 -> Las notificaciones push no incluyen datos personales sensibles; el detalle se consulta dentro de la app. | E34: ='RNF Notificaciones'!E9 -> Alta | F34: ='RNF Notificaciones'!F9 -> 0
B35: Los RNF provienen de las hojas generales «RNF …» y se actualizan automáticamente; edita el texto y el avance en su hoja general.
B38: Elaborado por: | C38: Alan David Santiago de Vicente, Ricardo Méndez Rodríguez, Eduardo Daniel Licea González
B39: Responsable: | C39: Equipo IncluTec — Ingeniería en Sistemas Computacionales
B40: Dependencias: | C40: API REST (FastAPI), Base de datos PostgreSQL; Expo Push Notifications
B41: Entrega: | C41: 28 de octubre de 2026
B44: Acotaciones de Avance
B45: 100% | C45: Completada
B46: 50% | C46: En proceso
B47: 0% | C47: No Iniciada
...

Sheet CAN-01 Vacantes
B1: ← Índice
B3: Requerimientos Funcionales
B4: Interfaz : CAN-01 — Vacantes (inicio del candidato)
B5: ID | C5: Requerimiento | D5: Descripción | E5: Prioridad | F5: Avance
B6: RF-01 | C6: Vacantes recomendadas | D6: Mostrar por defecto las vacantes publicadas ordenadas por compatibilidad descendente vía GET /vacantes/recomendadas (paginado de 20 con desplazamiento infinito). | E6: Alta | F6: 0
B7: RF-02 | C7: Búsqueda por texto | D7: Buscar por puesto, empresa o palabra clave (mínimo 3 caracteres) vía GET /vacantes?q=. | E7: Alta | F7: 0
B8: RF-03 | C8: Filtros | D8: Filtrar por modalidad, categoría, municipio/estado, jornada, salario mínimo, compatibilidad mínima y ajustes o condiciones de accesibilidad específicas (p. ej. «intérprete de LSM», «acceso con rampa»). | E8: Alta | F8: 0
B9: RF-04 | C9: Filtro «cubre mis necesidades» | D9: Opción para mostrar solo las vacantes que cubren todas las necesidades de ajuste registradas por el candidato. | E9: Alta | F9: 0
B10: RF-05 | C10: Tarjeta de vacante | D10: Cada tarjeta muestra puesto, empresa (con distintivo de empresa validada), modalidad, ubicación, porcentaje de compatibilidad e íconos de accesibilidad acompañados de texto. | E10: Media | F10: 0
B11: RF-06 | C11: Estado vacío y perfil incompleto | D11: Si no hay resultados, sugerir quitar filtros. Si el perfil está incompleto, mostrar un aviso con acceso a CAN-03 y CAN-04 explicando que las recomendaciones mejoran al completarlo. | E11: Media | F11: 0
B14: Requerimientos No Funcionales
B15: Interfaz : CAN-01 — Vacantes (inicio del candidato) · Accesibilidad, Pantallas móviles
B16: ID | C16: Nombre | D16: Descripción | E16: Prioridad | F16: Avance
B17: RNF-ACC-01 | C17: ='RNF Accesibilidad'!C6 -> Estándar de accesibilidad | D17: ='RNF Accesibilidad'!D6 -> Las interfaces cumplen las pautas WCAG 2.1 nivel AA. | E17: ='RNF Accesibilidad'!E6 -> Alta | F17: ='RNF Accesibilidad'!F6 -> 0
B18: RNF-ACC-02 | C18: ='RNF Accesibilidad'!C7 -> Lectores de pantalla | D18: ='RNF Accesibilidad'!D7 -> Todos los elementos interactivos tienen etiqueta, rol y estado accesibles (accessibilityLabel/Role/State en React Native; HTML semántico y ARIA en Laravel) y funcionan con TalkBack, VoiceOver y NVDA. | E18: ='RNF Accesibilidad'!E7 -> Alta | F18: ='RNF Accesibilidad'!F7 -> 0
B19: RNF-ACC-03 | C19: ='RNF Accesibilidad'!C8 -> Contraste | D19: ='RNF Accesibilidad'!D8 -> Contraste mínimo de 4.5:1 para texto normal y 3:1 para texto grande y componentes de interfaz. | E19: ='RNF Accesibilidad'!E8 -> Alta | F19: ='RNF Accesibilidad'!F8 -> 0
B20: RNF-ACC-04 | C20: ='RNF Accesibilidad'!C9 -> Texto escalable | D20: ='RNF Accesibilidad'!D9 -> La interfaz respeta el tamaño de fuente del sistema y admite hasta 200 % de ampliación sin pérdida de contenido ni funcionalidad. | E20: ='RNF Accesibilidad'!E9 -> Alta | F20: ='RNF Accesibilidad'!F9 -> 0
B21: RNF-ACC-05 | C21: ='RNF Accesibilidad'!C10 -> Áreas táctiles | D21: ='RNF Accesibilidad'!D10 -> Los componentes táctiles tienen un área mínima de 48 × 48 dp en Android y 44 × 44 pt en iOS. | E21: ='RNF Accesibilidad'!E10 -> Alta | F21: ='RNF Accesibilidad'!F10 -> 0
B22: RNF-ACC-06 | C22: ='RNF Accesibilidad'!C11 -> Información no dependiente del color | D22: ='RNF Accesibilidad'!D11 -> Estados, errores y porcentajes se comunican con texto o ícono además del color. | E22: ='RNF Accesibilidad'!E11 -> Alta | F22: ='RNF Accesibilidad'!F11 -> 0
B23: RNF-ACC-07 | C23: ='RNF Accesibilidad'!C12 -> Navegación por teclado | D23: ='RNF Accesibilidad'!D12 -> El panel web puede operarse completamente con teclado y la app admite teclado externo y control por interruptores (Switch Access / Control por botón), con foco visible y orden lógico. | E23: ='RNF Accesibilidad'!E12 -> Alta | F23: ='RNF Accesibilidad'!F12 -> 0
B24: RNF-ACC-08 | C24: ='RNF Accesibilidad'!C13 -> Lenguaje claro | D24: ='RNF Accesibilidad'!D13 -> Textos en lenguaje claro y sin tecnicismos; los errores de formulario indican qué campo falla y cómo corregirlo. | E24: ='RNF Accesibilidad'!E13 -> Media | F24: ='RNF Accesibilidad'!F13 -> 0
B25: RNF-ACC-09 | C25: ='RNF Accesibilidad'!C14 -> Movimiento reducido | D25: ='RNF Accesibilidad'!D14 -> Se respeta la preferencia de «reducir movimiento» del sistema y no hay contenido parpadeante. | E25: ='RNF Accesibilidad'!E14 -> Baja | F25: ='RNF Accesibilidad'!F14 -> 0
B26: RNF-MOV-01 | C26: ='RNF Operativas Móvil'!C6 -> Desempeño | D26: ='RNF Operativas Móvil'!D6 -> Tiempo de respuesta de las pantallas ≤ 2 s en el percentil 95 sobre red 4G. | E26: ='RNF Operativas Móvil'!E6 -> Alta | F26: ='RNF Operativas Móvil'!F6 -> 0
B27: RNF-MOV-02 | C27: ='RNF Operativas Móvil'!C7 -> Compatibilidad | D27: ='RNF Operativas Móvil'!D7 -> Ejecutable en Android 8+ e iOS 15+ con un solo código base (React Native + Expo). | E27: ='RNF Operativas Móvil'!E7 -> Alta | F27: ='RNF Operativas Móvil'!F7 -> 0
B28: RNF-MOV-03 | C28: ='RNF Operativas Móvil'!C8 -> Retroalimentación | D28: ='RNF Operativas Móvil'!D8 -> Toda acción que tarde más de 300 ms muestra un indicador de carga anunciado al lector de pantalla. | E28: ='RNF Operativas Móvil'!E8 -> Media | F28: ='RNF Operativas Móvil'!F8 -> 0
B29: RNF-MOV-04 | C29: ='RNF Operativas Móvil'!C9 -> Tolerancia a fallas de red | D29: ='RNF Operativas Móvil'!D9 -> La app conserva en caché el último listado de vacantes y postulaciones y avisa cuando no hay conexión; los formularios no pierden lo capturado. | E29: ='RNF Operativas Móvil'!E9 -> Media | F29: ='RNF Operativas Móvil'!F9 -> 0
B30: RNF-MOV-05 | C30: ='RNF Operativas Móvil'!C10 -> Orientación | D30: ='RNF Operativas Móvil'!D10 -> Las pantallas funcionan en orientación vertical y horizontal. | E30: ='RNF Operativas Móvil'!E10 -> Baja | F30: ='RNF Operativas Móvil'!F10 -> 0
B31: Los RNF provienen de las hojas generales «RNF …» y se actualizan automáticamente; edita el texto y el avance en su hoja general.
B34: Elaborado por: | C34: Alan David Santiago de Vicente, Ricardo Méndez Rodríguez, Eduardo Daniel Licea González
B35: Responsable: | C35: Equipo IncluTec — Ingeniería en Sistemas Computacionales
B36: Dependencias: | C36: API REST (FastAPI), Base de datos PostgreSQL; motor de compatibilidad
B37: Entrega: | C37: 28 de octubre de 2026
B40: Acotaciones de Avance
B41: 100% | C41: Completada
B42: 50% | C42: En proceso
B43: 0% | C43: No Iniciada
B46: Autorizado:

Sheet CAN-02 Detalle vacante
B1: ← Índice
B3: Requerimientos Funcionales
B4: Interfaz : CAN-02 — Detalle de vacante
B5: ID | C5: Requerimiento | D5: Descripción | E5: Prioridad | F5: Avance
B6: RF-01 | C6: Información de la vacante | D6: Obtener GET /vacantes/{id} y mostrar puesto, empresa, descripción, categoría, jornada, tipo de contrato, salario (si la empresa lo publica), ubicación y fecha de publicación. | E6: Alta | F6: 0
B7: RF-02 | C7: Requisitos | D7: Mostrar habilidades obligatorias y deseables, formación mínima y años de experiencia solicitados. | E7: Alta | F7: 0
B8: RF-03 | C8: Accesibilidad y ajustes | D8: Mostrar la modalidad, las condiciones de accesibilidad con las que ya cuenta el lugar de trabajo y los ajustes razonables que la empresa puede ofrecer bajo solicitud. | E8: Alta | F8: 0
B9: RF-04 | C9: Desglose de compatibilidad | D9: Obtener GET /vacantes/{id}/compatibilidad y mostrar el porcentaje con su detalle: habilidades que cumple y que le faltan, necesidades de ajuste cubiertas y no cubiertas, modalidad y formación. | E9: Alta | F9: 0
B10: RF-05 | C10: Postularse | D10: Enviar POST /postulaciones con {vacante_id, mensaje (opcional, ≤ 500 caracteres), compartir_ajustes}; confirmar antes de enviar. Si el API responde 409, indicar que ya existe una postulación a esa vacante. | E10: Alta | F10: 0
B11: RF-06 | C11: Requisito de perfil mínimo | D11: Deshabilitar «Postularme» y explicar el motivo si el perfil no tiene nombre, municipio, al menos una habilidad y al menos una formación académica. | E11: Media | F11: 0
B12: RF-07 | C12: Consentimiento de ajustes | D12: Antes de postularse, preguntar si desea compartir sus necesidades de ajuste con la empresa; por defecto se toma su preferencia de CAN-03. | E12: Alta | F12: 0
B13: RF-08 | C13: Reportar vacante | D13: Permitir reportar la vacante (POST /reportes) eligiendo un motivo del catálogo y una descripción opcional (≤ 500 caracteres). | E13: Media | F13: 0
B14: RF-09 | C14: Ver empresa | D14: Enlazar a la ficha de la empresa en CAN-07. | E14: Baja | F14: 0
B17: Requerimientos No Funcionales
B18: Interfaz : CAN-02 — Detalle de vacante · Accesibilidad, Privacidad y datos sensibles, Pantallas móviles
B19: ID | C19: Nombre | D19: Descripción | E19: Prioridad | F19: Avance
B20: RNF-ACC-01 | C20: ='RNF Accesibilidad'!C6 -> Estándar de accesibilidad | D20: ='RNF Accesibilidad'!D6 -> Las interfaces cumplen las pautas WCAG 2.1 nivel AA. | E20: ='RNF Accesibilidad'!E6 -> Alta | F20: ='RNF Accesibilidad'!F6 -> 0
B21: RNF-ACC-02 | C21: ='RNF Accesibilidad'!C7 -> Lectores de pantalla | D21: ='RNF Accesibilidad'!D7 -> Todos los elementos interactivos tienen etiqueta, rol y estado accesibles (accessibilityLabel/Role/State en React Native; HTML semántico y ARIA en Laravel) y funcionan con TalkBack, VoiceOver y NVDA. | E21: ='RNF Accesibilidad'!E7 -> Alta | F21: ='RNF Accesibilidad'!F7 -> 0
B22: RNF-ACC-03 | C22: ='RNF Accesibilidad'!C8 -> Contraste | D22: ='RNF Accesibilidad'!D8 -> Contraste mínimo de 4.5:1 para texto normal y 3:1 para texto grande y componentes de interfaz. | E22: ='RNF Accesibilidad'!E8 -> Alta | F22: ='RNF Accesibilidad'!F8 -> 0
B23: RNF-ACC-04 | C23: ='RNF Accesibilidad'!C9 -> Texto escalable | D23: ='RNF Accesibilidad'!D9 -> La interfaz respeta el tamaño de fuente del sistema y admite hasta 200 % de ampliación sin pérdida de contenido ni funcionalidad. | E23: ='RNF Accesibilidad'!E9 -> Alta | F23: ='RNF Accesibilidad'!F9 -> 0
B24: RNF-ACC-05 | C24: ='RNF Accesibilidad'!C10 -> Áreas táctiles | D24: ='RNF Accesibilidad'!D10 -> Los componentes táctiles tienen un área mínima de 48 × 48 dp en Android y 44 × 44 pt en iOS. | E24: ='RNF Accesibilidad'!E10 -> Alta | F24: ='RNF Accesibilidad'!F10 -> 0
B25: RNF-ACC-06 | C25: ='RNF Accesibilidad'!C11 -> Información no dependiente del color | D25: ='RNF Accesibilidad'!D11 -> Estados, errores y porcentajes se comunican con texto o ícono además del color. | E25: ='RNF Accesibilidad'!E11 -> Alta | F25: ='RNF Accesibilidad'!F11 -> 0
B26: RNF-ACC-07 | C26: ='RNF Accesibilidad'!C12 -> Navegación por teclado | D26: ='RNF Accesibilidad'!D12 -> El panel web puede operarse completamente con teclado y la app admite teclado externo y control por interruptores (Switch Access / Control por botón), con foco visible y orden lógico. | E26: ='RNF Accesibilidad'!E12 -> Alta | F26: ='RNF Accesibilidad'!F12 -> 0
B27: RNF-ACC-08 | C27: ='RNF Accesibilidad'!C13 -> Lenguaje claro | D27: ='RNF Accesibilidad'!D13 -> Textos en lenguaje claro y sin tecnicismos; los errores de formulario indican qué campo falla y cómo corregirlo. | E27: ='RNF Accesibilidad'!E13 -> Media | F27: ='RNF Accesibilidad'!F13 -> 0
B28: RNF-ACC-09 | C28: ='RNF Accesibilidad'!C14 -> Movimiento reducido | D28: ='RNF Accesibilidad'!D14 -> Se respeta la preferencia de «reducir movimiento» del sistema y no hay contenido parpadeante. | E28: ='RNF Accesibilidad'!E14 -> Baja | F28: ='RNF Accesibilidad'!F14 -> 0
B29: RNF-PRV-01 | C29: ='RNF Privacidad'!C6 -> Cumplimiento legal | D29: ='RNF Privacidad'!D6 -> El tratamiento de datos personales cumple la Ley Federal de Protección de Datos Personales en Posesión de los Particulares, con aviso de privacidad y consentimiento expreso para datos sensibles. | E29: ='RNF Privacidad'!E6 -> Alta | F29: ='RNF Privacidad'!F6 -> 0
B30: RNF-PRV-02 | C30: ='RNF Privacidad'!C7 -> Minimización de datos | D30: ='RNF Privacidad'!D7 -> El sistema registra necesidades de ajuste y no diagnósticos, tipos de discapacidad ni documentos médicos. | E30: ='RNF Privacidad'!E7 -> Alta | F30: ='RNF Privacidad'!F7 -> 0
B31: RNF-PRV-03 | C31: ='RNF Privacidad'!C8 -> Control del candidato | D31: ='RNF Privacidad'!D8 -> Las necesidades de ajuste solo son visibles para el candidato y para las empresas a cuyas vacantes se postuló con consentimiento; el administrador solo ve datos agregados. | E31: ='RNF Privacidad'!E8 -> Alta | F31: ='RNF Privacidad'!F8 -> 0
B32: RNF-PRV-04 | C32: ='RNF Privacidad'!C9 -> Derechos ARCO | D32: ='RNF Privacidad'!D9 -> El candidato puede consultar, corregir y eliminar sus datos; la eliminación anonimiza sus postulaciones históricas en un plazo máximo de 30 días. | E32: ='RNF Privacidad'!E9 -> Alta | F32: ='RNF Privacidad'!F9 -> 0
B33: RNF-PRV-05 | C33: ='RNF Privacidad'!C10 -> Registros sin datos sensibles | D33: ='RNF Privacidad'!D10 -> Los logs del servidor y los mensajes push no incluyen necesidades de ajuste ni datos de contacto. | E33: ='RNF Privacidad'!E10 -> Alta | F33: ='RNF Privacidad'!F10 -> 0
B34: RNF-MOV-01 | C34: ='RNF Operativas Móvil'!C6 -> Desempeño | D34: ='RNF Operativas Móvil'!D6 -> Tiempo de respuesta de las pantallas ≤ 2 s en el percentil 95 sobre red 4G. | E34: ='RNF Operativas Móvil'!E6 -> Alta | F34: ='RNF Operativas Móvil'!F6 -> 0
B35: RNF-MOV-02 | C35: ='RNF Operativas Móvil'!C7 -> Compatibilidad | D35: ='RNF Operativas Móvil'!D7 -> Ejecutable en Android 8+ e iOS 15+ con un solo código base (React Native + Expo). | E35: ='RNF Operativas Móvil'!E7 -> Alta | F35: ='RNF Operativas Móvil'!F7 -> 0
B36: RNF-MOV-03 | C36: ='RNF Operativas Móvil'!C8 -> Retroalimentación | D36: ='RNF Operativas Móvil'!D8 -> Toda acción que tarde más de 300 ms muestra un indicador de carga anunciado al lector de pantalla. | E36: ='RNF Operativas Móvil'!E8 -> Media | F36: ='RNF Operativas Móvil'!F8 -> 0
B37: RNF-MOV-04 | C37: ='RNF Operativas Móvil'!C9 -> Tolerancia a fallas de red | D37: ='RNF Operativas Móvil'!D9 -> La app conserva en caché el último listado de vacantes y postulaciones y avisa cuando no hay conexión; los formularios no pierden lo capturado. | E37: ='RNF Operativas Móvil'!E9 -> Media | F37: ='RNF Operativas Móvil'!F9 -> 0
